import React from 'react';

interface ErrorBoundaryProps {
  children: React.ReactNode;
  fallback?: React.ComponentType<{ error: Error; retry: () => void }>;
  onError?: (error: Error, errorInfo: React.ErrorInfo) => void;
}

interface ErrorBoundaryState {
  hasError: boolean;
  error: Error | null;
}

const DefaultErrorFallback = ({ error, retry }: { error: Error; retry: () => void }) => (
  <div className="min-h-screen flex items-center justify-center p-4">
    <div className="text-center">
      <h2 className="text-lg font-semibold mb-2">Something went wrong</h2>
      <p className="text-muted-foreground mb-4">
        {error.message || 'An unexpected error occurred'}
      </p>
      <button 
        onClick={retry}
        className="px-4 py-2 bg-primary text-primary-foreground rounded-md hover:bg-primary/90"
      >
        Try again
      </button>
    </div>
  </div>
);

export class ErrorBoundary extends React.Component<ErrorBoundaryProps, ErrorBoundaryState> {
  constructor(props: ErrorBoundaryProps) {
    super(props);
    this.state = { hasError: false, error: null };
  }

  static getDerivedStateFromError(error: Error): ErrorBoundaryState {
    return { hasError: true, error };
  }

  componentDidCatch(error: Error, errorInfo: React.ErrorInfo) {
    this.props.onError?.(error, errorInfo);
    console.error('ErrorBoundary caught an error:', error, errorInfo);
  }

  retry = () => {
    this.setState({ hasError: false, error: null });
  };

  render() {
    if (this.state.hasError && this.state.error) {
      const FallbackComponent = this.props.fallback || DefaultErrorFallback;
      return <FallbackComponent error={this.state.error} retry={this.retry} />;
    }

    return this.props.children;
  }
}